Workbook

Sheet DB2_MutualFunds
A1: InvestorID | B1: InvestorName | C1: Age | D1: City | E1: Fund_Name | F1: Fund_Category | G1: Units_Held | H1: NAV | I1: Invested_Amount | J1: Current_Value | K1: Returns_Pct | L1: Investment_Date | M1: Fund_House | N1: Risk_Level | O1: SIP_Status | R1: rank
A2: INV2001 | B2: Renu Saxena | C2: 47 | D2: Pune | E2: HDFC Mid-Cap Opportunities | F2: Mid Cap | G2: 1934.73 | H2: 487.56 | I2: 118980.05 | J2: 122535.17 | K2: 2.99 | L2: 44008 | M2: HDFC AMC | N2: Moderate | O2: Paused | R2: =RANK(J2,$J$2:$J$151,0) -> 127
A3: INV2002 | B3: Sameer Joshi | C3: 38 | D3: Delhi | E3: SBI Small Cap Fund | F3: Small Cap | G3: 3658.7 | H3: 434.03 | I3: 351741.66 | J3: 341639.29 | K3: -2.87 | L3: 45108 | M3: SBI Funds | N3: High | O3: Stopped | R3: =RANK(J3,$J$2:$J$151,0) -> 77
A4: INV2003 | B4: Tara Pillai | C4: 53 | D4: Bangalore | E4: Mirae Asset Emerging Bluechip | F4: Large & Mid Cap | G4: 1037.37 | H4: 583.34 | I4: 296261.55 | J4: 568830.74 | K4: 92 | L4: 44596 | M4: Mirae Asset | N4: Moderate | O4: Active | R4: =RANK(J4,$J$2:$J$151,0) -> 32
A5: INV2004 | B5: Uday Shetty | C5: 46 | D5: Hyderabad | E5: Parag Parikh Flexi Cap | F5: Flexi Cap | G5: 4314.39 | H5: 185.82 | I5: 233434.23 | J5: 254828.78 | K5: 9.17 | L5: 44992 | M5: PPFAS | N5: Moderate | O5: Active | R5: =RANK(J5,$J$2:$J$151,0) -> 95
A6: INV2005 | B6: Vandana Kapoor | C6: 43 | D6: Chennai | E6: Kotak Gilt Fund | F6: Debt - Gilt | G6: 460.68 | H6: 579.01 | I6: 340301.87 | J6: 329593.59 | K6: -3.15 | L6: 44478 | M6: Kotak Mahindra | N6: Low | O6: Paused | R6: =RANK(J6,$J$2:$J$151,0) -> 80
A7: INV2006 | B7: Waqar Ahmad | C7: 47 | D7: Ahmedabad | E7: ICICI Pru Technology Fund | F7: Sectoral - Tech | G7: 261.12 | H7: 455.2 | I7: 215476.97 | J7: 288613.62 | K7: 33.94 | L7: 44925 | M7: ICICI Pru | N7: High | O7: Active | R7: =RANK(J7,$J$2:$J$151,0) -> 85
A8: INV2007 | B8: Xeniya Roy | C8: 27 | D8: Kolkata | E8: Nippon India Gold ETF | F8: ETF - Gold | G8: 2337.33 | H8: 722.19 | I8: 304727.02 | J8: 660819.14 | K8: 116.86 | L8: 44563 | M8: Nippon India | N8: Moderate | O8: Paused | R8: =RANK(J8,$J$2:$J$151,0) -> 26
A9: INV2008 | B9: Yashvi Patel | C9: 30 | D9: Mumbai | E9: Axis Bluechip Fund | F9: Large Cap | G9: 1118.33 | H9: 738.2 | I9: 84601.92 | J9: 162349.63 | K9: 91.9 | L9: 45050 | M9: Axis AMC | N9: Low | O9: Stopped | R9: =RANK(J9,$J$2:$J$151,0) -> 114
A10: INV2009 | B10: Zara Khan | C10: 33 | D10: Pune | E10: HDFC Mid-Cap Opportunities | F10: Mid Cap | G10: 4722.36 | H10: 535.03 | I10: 23345.77 | J10: 20578.37 | K10: -11.85 | L10: 44801 | M10: HDFC AMC | N10: Moderate | O10: Active | R10: =RANK(J10,$J$2:$J$151,0) -> 148
A11: INV2010 | B11: Aakash Gupta | C11: 65 | D11: Delhi | E11: SBI Small Cap Fund | F11: Small Cap | G11: 4107.36 | H11: 83.3 | I11: 215583.01 | J11: 208280.24 | K11: -3.39 | L11: 44465 | M11: SBI Funds | N11: High | O11: Active | R11: =RANK(J11,$J$2:$J$151,0) -> 105
A12: INV2011 | B12: Bhavna Nair | C12: 61 | D12: Bangalore | E12: Mirae Asset Emerging Bluechip | F12: Large & Mid Cap | G12: 78.06 | H12: 277.16 | I12: 264084.03 | J12: 296057.33 | K12: 12.11 | L12: 43944 | M12: Mirae Asset | N12: Moderate | O12: Paused | R12: =RANK(J12,$J$2:$J$151,0) -> 84
A13: INV2012 | B13: Chetan Mehta | C13: 62 | D13: Hyderabad | E13: Parag Parikh Flexi Cap | F13: Flexi Cap | G13: 1096.6 | H13: 220.91 | I13: 205013.49 | J13: 385655.62 | K13: 88.11 | L13: 44555 | M13: PPFAS | N13: Moderate | O13: Active | R13: =RANK(J13,$J$2:$J$151,0) -> 67
... A151: INV2150 | B151: Aakash Gupta | C151: 35 | D151: Ahmedabad | E151: ICICI Pru Technology Fund | F151: Sectoral - Tech | G151: 4002.2 | H151: 331.95 | I151: 399545.71 | J151: 755821.87 | K151: 89.17 | L151: 44586 | M151: ICICI Pru | N151: High | O151: Active | R151: =RANK(J151,$J$2:$J$151,0) -> 16

Sheet Q2_MutualFunds
A1: 📝 Practice Questions — DB2_MutualFunds
A2: 🟢 Basic = Green 🟡 Medium = Yellow 🟠 Intermediate = Orange 🔴 Hard = Red | Write your formula in Column E (Your Answer)
A3: # | B3: Level | C3: Question | D3: Hint / Formula Guide | E3: Your Answer (type formula here)
A4: ▶ BASIC QUESTIONS
A5: 1 | B5: Basic | C5: Count total investor records in this database. | D5: =COUNTA(A2:A151) -> 86 | E5: =COUNTA(DB2_MutualFunds!A2:A151) -> 150
A6: 2 | B6: Basic | C6: Find total Invested_Amount across all investors. | D6: =SUM(I2:I151) -> 0 | E6: =SUM(DB2_MutualFunds!I2:I151) -> 36561470
A7: 3 | B7: Basic | C7: Find total Current_Value across all investors. | D7: =SUM(J2:J151) -> 0 | E7: =SUM(DB2_MutualFunds!J2:J151) -> 56460766
A8: 4 | B8: Basic | C8: What is the MAX Returns_Pct in the dataset? | D8: =MAX(K2:K151) -> 0 | E8: =MAX(DB2_MutualFunds!K2:K151) -> 119.51
A9: 5 | B9: Basic | C9: What is the MIN Returns_Pct (might be negative)? | D9: =MIN(K2:K151) -> 0 | E9: =MIN(DB2_MutualFunds!K2:K151) -> -14.51
A10: 6 | B10: Basic | C10: Count how many investors have SIP_Status = 'Active'. | D10: =COUNTIF(O2:O151,"Active") -> 0 | E10: =COUNTIF(DB2_MutualFunds!O2:O151,"active") -> 75
A11: 7 | B11: Basic | C11: What is the average NAV across all fund investments? | D11: =AVERAGE(H2:H151) -> #DIV/0! | E11: =AVERAGE(DB2_MutualFunds!H2:H151) -> 406.3052
A12: 8 | B12: Basic | C12: Find the average Units_Held. | D12: =AVERAGE(G2:G151) -> #DIV/0! | E12: =AVERAGE(DB2_MutualFunds!G2:G151) -> 2385.9016
A13: 9 | B13: Basic | C13: How many investors are in the 'Small Cap' fund category? | D13: =COUNTIF(F2:F151,"Small Cap") -> 0 | E13: =COUNTIF(DB2_MutualFunds!F2:F151,"small cap") -> 19
A14: 10 | B14: Basic | C14: Find the sum of Invested_Amount for 'Large Cap' category. | D14: =SUMIF(F2:F151,"Large Cap",I2:I151) -> 0 | E14: =SUMIF(DB2_MutualFunds!F2:F151,"large cap",DB2_MutualFunds!I2:I151) -> 3256009.2
A15: 11 | B15: Basic | C15: Use MAX to find the highest Current_Value. | D15: =MAX(J2:J151) -> 0 | E15: =MAX(DB2_MutualFunds!J2:J151) -> 1031522.7
A16: 12 | B16: Basic | C16: Use MIN to find the lowest Invested_Amount. | D16: =MIN(I2:I151) -> 0 | E16: =MIN(DB2_MutualFunds!I2:I151) -> 7372.84
A17: 13 | B17: Basic | C17: How many investors are from Mumbai? | D17: =COUNTIF(D2:D151,"Mumbai") | E17: =COUNTIF(DB2_MutualFunds!D2:D151,"mumbai") -> 18
A18: 14 | B18: Basic | C18: Find total Invested_Amount for investors from Bangalore. | D18: =SUMIF(D2:D151,"Bangalore",I2:I151) -> 0 | E18: =SUMIF(DB2_MutualFunds!D2:D151,"bangalore",DB2_MutualFunds!I2:I151) -> 4576225.7
A19: 15 | B19: Basic | C19: Use COUNTA to count how many Fund_Name entries are non-empty. | D19: =COUNTA(E2:E151) -> 41 | E19: =COUNTA(DB2_MutualFunds!E2:E151) -> 150
A20: 16 | B20: Basic | C20: Use UPPER() on Fund_House in M2. | D20: =UPPER(M2) | E20: =UPPER(DB2_MutualFunds!M2) -> HDFC AMC
A21: 17 | B21: Basic | C21: Use LEN() to find character length of Fund_Name in E2. | D21: =LEN(E2) -> 0 | E21: =LEN(DB2_MutualFunds!E2) -> 26
A22: 18 | B22: Basic | C22: Use LEFT() to get first 4 chars of InvestorID in A2. | D22: =LEFT(A2,4) -> 🟢 Ba | E22: =LEFT(DB2_MutualFunds!A2,4) -> INV2
A23: 19 | B23: Basic | C23: Use TODAY() and subtract Investment_Date in L2 to find days since investment. | D23: =TODAY()-L2 (format result as number) -> #NAME? | E23: =TODAY()-DB2_MutualFunds!L2 -> 2203
A24: 20 | B24: Basic | C24: Count investors with Risk_Level = 'High'. | D24: =COUNTIF(N2:N151,"High") -> 0 | E24: =COUNTIF(DB2_MutualFunds!N2:N151,"high") -> 38
A25: ▶ MEDIUM QUESTIONS
A26: 21 | B26: Medium | C26: Find total Current_Value for 'High' risk AND SIP_Status = 'Active'. | D26: =SUMIFS(J2:J151,N2:N151,"High",O2:O151,"Active") -> 0 | E26: =SUMIFS(DB2_MutualFunds!J2:J151,DB2_MutualFunds!N2:N151,"high",DB2_MutualFunds!O2:O151,"active") -> 8619615.4
A27: 22 | B27: Medium | C27: Count investors with Returns_Pct > 20%. | D27: =COUNTIF(K2:K151,">20") -> 0 | E27: =COUNTIF(DB2_MutualFunds!K2:K151,">20") -> 109
A28: 23 | B28: Medium | C28: Use VLOOKUP to find Current_Value for InvestorID 'INV2050'. (Column 10) | D28: =VLOOKUP("INV2050",A2:J151,10,0) -> #N/A | E28: =VLOOKUP(DB2_MutualFunds!A51,DB2_MutualFunds!A2:O152,10,) -> 758257.34
A29: 24 | B29: Medium | C29: Use XLOOKUP to find Fund_Name for investor 'INV2075'. | D29: =_xludf.XLOOKUP("INV2075",A2:A151,E2:E151,"Not Found") -> #NAME? | E29: =_xlfn.XLOOKUP(DB2_MutualFunds!A76,DB2_MutualFunds!A2:A152,DB2_MutualFunds!E2:E152) -> Mirae Asset Emerging Bluechip
A30: 25 | B30: Medium | C30: Use IF to classify returns: >20 = 'Excellent', 0-20 = 'Good', <0 = 'Loss'. | D30: =IF(K2>20,"Excellent",IF(K2>=0,"Good","Loss")) drag down -> #VALUE! | E30: =IF(K2>20,"excellent",IF(K2>0,"good","bad")) -> bad
A31: 26 | B31: Medium | C31: Average Returns_Pct for 'Mid Cap' category only. | D31: =AVERAGEIF(F2:F151,"Mid Cap",K2:K151) -> #DIV/0! | E31: =AVERAGEIF(DB2_MutualFunds!F2:F151,"mid cap",DB2_MutualFunds!K2:K151) -> 60.646842
A32: 27 | B32: Medium | C32: Use CONCATENATE to combine InvestorName and City: 'Renu Saxena (Pune)'. | D32: =C2&" ("&D2&")" -> () | E32: =CONCATENATE(DB2_MutualFunds!B2,"-",DB2_MutualFunds!D2) -> Renu Saxena-Pune
A33: 28 | B33: Medium | C33: Sort the entire table by Returns_Pct, highest first. | D33: Data → Sort → Column K → Largest to Smallest | E33: sorted
A34: 29 | B34: Medium | C34: Filter to show only rows where Fund_Category = 'Flexi Cap'. | D34: Data → Filter → Fund_Category → Flexi Cap | E34: sorted
A35: 30 | B35: Medium | C35: Use SUMPRODUCT to calculate total portfolio gain (Current_Value - Invested_Amount). | E35: {=SUMPRODUCT(DB2_MutualFunds!J2:J151-DB2_MutualFunds!I2:I151)} -> 19899296
A36: 31 | B36: Medium | C36: Use IFERROR with VLOOKUP for 'INV9999' to show 'ID Not Found'. | D36: =IFERROR(VLOOKUP("INV9999",A2:J151,2,0),"ID Not Found") -> ID Not Found | E36: =IFERROR(VLOOKUP("INV9999",A2:O151,2,FALSE),"ID Not Found") -> ID Not Found
A37: 32 | B37: Medium | C37: Find MAX Current_Value for investors from Delhi. | D37: =_xludf.MAXIFS(J2:J151,D2:D151,"Delhi") -> #NAME? | E37: =_xlfn.MAXIFS(DB2_MutualFunds!J2:J151,DB2_MutualFunds!D2:D151,"delhi") -> 903690.25
A38: 33 | B38: Medium | C38: Find AVERAGE Invested_Amount for investors aged > 40. | D38: =AVERAGEIFS(I2:I151,C2:C151,">40") -> #DIV/0! | E38: =AVERAGEIF(DB2_MutualFunds!C2:C151,">40",DB2_MutualFunds!I2:I151) -> 245873.66
A39: 34 | B39: Medium | C39: Use TEXT() to format Investment_Date as 'Month YYYY' (e.g., 'January 2022'). | D39: =TEXT(L2,"MMMM YYYY") -> January 1900 | E39: =TEXT(DB2_MutualFunds!L2,"mmmm yyyy") -> June 2020
A40: 35 | B40: Medium | C40: Use RANK() to rank each investor by Current_Value (1 = highest). | E40: =RANK(DB2_MutualFunds!J2,DB2_MutualFunds!J2:J151,0) -> 127
...
