Workbook

Sheet Q1_BankTransactions
A1: 📝 Practice Questions — DB1_BankTransactions
A2: 🟢 Basic = Green 🟡 Medium = Yellow 🟠 Intermediate = Orange 🔴 Hard = Red | Write your formula in Column E (Your Answer)
A3: # | B3: Level | C3: Question | D3: Hint / Formula Guide | E3: Your Answer (type formula here)
A4: ▶ BASIC QUESTIONS
A5: 1 | B5: Basic | C5: Count the total number of transactions in this dataset. | D5: Use: =COUNTA(A2:A71) | E5: =COUNTA(A1:A70) -> 70
A6: 2 | B6: Basic | C6: Find the total Amount of all transactions using SUM. | D6: Use: =SUM(G2:G71) | E6: =SUM(DB1_BankTransactions!G2:G71) -> 5451207.2
A7: 3 | B7: Basic | C7: What is the highest (MAX) Credit Score in the dataset? | D7: Use: =MAX(L2:L71) | E7: =MAX(DB1_BankTransactions!L2:L71) -> 850
A8: 4 | B8: Basic | C8: What is the lowest (MIN) Balance_After across all rows? | D8: Use: =MIN(H2:H71) | E8: =MIN(DB1_BankTransactions!H2:H71) -> 2075.53
A9: 5 | B9: Basic | C9: What is the Average transaction Amount? | D9: Use: =AVERAGE(G2:G71) | E9: =AVERAGE(DB1_BankTransactions!G2:G71) -> 77874.389
A10: 6 | B10: Basic | C10: Find how many transactions have Transaction_Type = 'Credit'. | D10: Use: =COUNTIF(F2:F71,"Credit") | E10: =COUNTIF(DB1_BankTransactions!F2:F71,"credit") -> 14
A11: 7 | B11: Basic | C11: Display the CustomerName from row 5 using a direct cell reference. | D11: Use: =C6 (row 5 of data is row 6 in sheet) | E11: =DB1_BankTransactions!C6 -> Meera Nair
A12: 8 | B12: Basic | C12: Use COUNTA to count how many Branch entries are filled. | D12: Use: =COUNTA(J2:J71) | E12: =COUNTA(DB1_BankTransactions!J2:J71) -> 70
A13: 9 | B13: Basic | C13: What is the sum of all transactions in the 'Savings' account type? | D13: Use: =SUMIF(E2:E71,"Savings",G2:G71) | E13: =SUMIF(DB1_BankTransactions!E2:E71,"savings",DB1_BankTransactions!G2:G71) -> 1031389.6
A14: 10 | B14: Basic | C14: How many customers are marked as Premium = 'Yes'? | D14: Use: =COUNTIF(M2:M71,"Yes") | E14: =COUNTIF(DB1_BankTransactions!M2:M71,"yes") -> 20
A15: 11 | B15: Basic | C15: What is the AVERAGE Credit Score? | D15: Use: =AVERAGE(L2:L71) | E15: =AVERAGE(DB1_BankTransactions!L2:L71) -> 704.55714
A16: 12 | B16: Basic | C16: Count how many transactions happened in the 'BKC' branch. | D16: Use: =COUNTIF(J2:J71,"BKC") | E16: =COUNTIF(DB1_BankTransactions!J2:J71,"bkc") -> 10
A17: 13 | B17: Basic | C17: Find the MAX Amount for 'Debit' transaction type. | D17: Use: =MAXIFS(G2:G71,F2:F71,"Debit") | E17: =_xlfn.MAXIFS(DB1_BankTransactions!G2:G71,DB1_BankTransactions!F2:F71,"debit") -> 154453.32
A18: 14 | B18: Basic | C18: What is the sum of Balance_After for all 'Current' account holders? | D18: Use: =SUMIF(E2:E71,"Current",H2:H71) | E18: =SUMIF(DB1_BankTransactions!E2:E71,"current",DB1_BankTransactions!H2:H71) -> 3378929.9
A19: 15 | B19: Basic | C19: Use LEFT() to extract first 4 characters of TxnID from A2. | D19: Use: =LEFT(A2,4) | E19: =LEFT(DB1_BankTransactions!A2,4) -> TXN1
A20: 16 | B20: Basic | C20: Use LEN() to find the length of CustomerName in C2. | D20: Use: =LEN(C2) | E20: =LEN(DB1_BankTransactions!C2) -> 10
A21: 17 | B21: Basic | C21: Use UPPER() to convert the Branch name in J2 to uppercase. | D21: Use: =UPPER(J2) | E21: =UPPER(DB1_BankTransactions!J2) -> ANDHERI
A22: 18 | B22: Basic | C22: Use LOWER() to convert the city in D2 to lowercase. | D22: Use: =LOWER(D2) | E22: =LOWER(DB1_BankTransactions!D2) -> delhi
A23: 19 | B23: Basic | C23: Use TRIM() to clean any extra spaces from C2. | D23: Use: =TRIM(C2) | E23: =TRIM(DB1_BankTransactions!C2) -> Sneha Iyer
A24: 20 | B24: Basic | C24: Use TODAY() to display today's date. | D24: Use: =TODAY() | E24: =TODAY() -> 46211
A25: ▶ MEDIUM QUESTIONS
A26: 21 | B26: Medium | C26: Find the total Amount for transactions where City = 'Mumbai' AND Transaction_Type = 'Credit'. | D26: Use: =SUMIFS(G2:G71, D2:D71,"Mumbai", F2:F71,"Credit") | E26: =SUMIFS(DB1_BankTransactions!G2:G71,DB1_BankTransactions!D2:D71,"mumbai",DB1_BankTransactions!F2:F71,"credit") -> 90275.28
A27: 22 | B27: Medium | C27: Count how many 'Premium' customers ('Yes') did a 'Debit' transaction. | D27: Use: =COUNTIFS(M2:M71,"Yes",F2:F71,"Debit") | E27: =COUNTIFS(DB1_BankTransactions!M2:M71,"yes",DB1_BankTransactions!F2:F71,"debit") -> 3
A28: 23 | B28: Medium | C28: Use VLOOKUP to find the Branch of TxnID 'TXN10005'. (Create a lookup table on the side.) | D28: Hint: =VLOOKUP("TXN10005",A2:J71,10,0) | E28: =VLOOKUP(DB1_BankTransactions!O6,DB1_BankTransactions!O2:P71,2,FALSE) -> #N/A
A29: 24 | B29: Medium | C29: Use IF() to label each transaction: if Amount>50000 show 'High Value', else 'Normal'. | D29: Use: =IF(G2>50000,"High Value","Normal") — drag down | E29: =IF(DB1_BankTransactions!G3,"high value","normal") -> high value
A30: 25 | B30: Medium | C30: Use AVERAGEIF to find average Amount for 'Savings' account type. | D30: Use: =AVERAGEIF(E2:E71,"Savings",G2:G71) | E30: =AVERAGEIF(DB1_BankTransactions!E2:E71,"savings",DB1_BankTransactions!G2:G71) -> 73670.687
A31: 26 | B31: Medium | C31: Use AVERAGEIFS to find average Amount for 'Mumbai' city AND 'Credit' transaction. | D31: Use: =AVERAGEIFS(G2:G71,D2:D71,"Mumbai",F2:F71,"Credit") | E31: =AVERAGEIFS(DB1_BankTransactions!G2:G71,DB1_BankTransactions!D2:D71,"mumbai",DB1_BankTransactions!F2:F71,"credit") -> 45137.64
A32: 27 | B32: Medium | C32: Use CONCATENATE (or &) to combine CustomerName and City with ' - ' between them. | D32: Use: =C2&" - "&D2 or =CONCATENATE(C2," - ",D2) | E32: =CONCATENATE(DB1_BankTransactions!C2,"-",DB1_BankTransactions!D2) -> Sneha Iyer-Delhi
A33: 28 | B33: Medium | C33: Use TEXT() to format the TxnDate in B column as 'DD/MM/YYYY'. | D33: Use: =TEXT(I2,"DD/MM/YYYY") | E33: wrong question
A34: 29 | B34: Medium | C34: Use IFERROR to wrap a VLOOKUP for 'TXN99999' (which doesn't exist) and show 'Not Found'. | D34: Use: =IFERROR(VLOOKUP("TXN99999",A2:J71,2,0),"Not Found") | E34: =IFERROR(VLOOKUP("txn9999",DB1_BankTransactions!A2:J71,2,FALSE),"not found") -> not found
A35: 30 | B35: Medium | C35: Count distinct cities — use SUMPRODUCT+COUNTIF formula. | D35: Use: =SUMPRODUCT(1/COUNTIF(D2:D71,D2:D71)) | E35: =SUMPRODUCT(DB1_BankTransactions!D2:D71) -> 0
A36: 31 | B36: Medium | C36: Find the RANK of Amount in G2 among all amounts (largest = rank 1). | D36: Use: =RANK(G2,G$2:G$71,0) — drag down | E36: =RANK(DB1_BankTransactions!G2,DB1_BankTransactions!G2:G71,0) -> 1
A37: 32 | B37: Medium | C37: Apply Conditional Formatting on the Amount column: highlight red if Amount > 100000. | D37: Home → Conditional Formatting → New Rule → Format cells where value > 100000 | E37: done
A38: 33 | B38: Medium | C38: Use XLOOKUP to find the Relationship_Manager for TxnID 'TXN10010'. | D38: Use: =XLOOKUP("TXN10010",A2:A71,K2:K71,"Not Found") | E38: =_xlfn.XLOOKUP(DB1_BankTransactions!A11,DB1_BankTransactions!A2:A71,DB1_BankTransactions!K2:K71) -> Suresh Nair
A39: 34 | B39: Medium | C39: Sort the entire table by Amount (largest to smallest) using Data → Sort. | D39: Data → Sort → Column G → Largest to Smallest | E39: sorted
A40: 35 | B40: Medium | C40: Filter the dataset to show only rows where Branch = 'Powai'. | D40: Data → Filter → Click Branch dropdown → Select Powai | E40: sorted
...

Sheet DB1_BankTransactions
A1: TxnID | B1: CustomerID | C1: CustomerName | D1: City | E1: Account_Type | F1: Transaction_Type | G1: Amount | H1: Balance_After | I1: TxnDate | J1: Branch | K1: Relationship_Manager | L1: Credit_Score | M1: Is_Premium
A2: TXN10001 | B2: CUST1002 | C2: Sneha Iyer | D2: Delhi | E2: Current | F2: Debit | G2: 154453.32 | H2: 13480.37 | I2: 45432 | J2: Andheri | K2: Rahul Verma | L2: 705 | M2: No
A3: TXN10002 | B3: CUST1003 | C3: Arjun Singh | D3: Pune | E3: Fixed Deposit | F3: Transfer | G3: 147790.62 | H3: 368499.14 | I3: 45638 | J3: Powai | K3: Anjali Mehta | L3: 624 | M3: No
A4: TXN10003 | B4: CUST1004 | C4: Pooja Shah | D4: Bangalore | E4: Recurring Deposit | F4: EMI | G4: 145980.81 | H4: 16859.56 | I4: 45339 | J4: Thane | K4: Suresh Nair | L4: 691 | M4: No
A5: TXN10004 | B5: CUST1005 | C5: Nikhil Jain | D5: Chennai | E5: NRI | F5: Interest | G5: 144136.45 | H5: 301407.35 | I5: 45579 | J5: Dadar | K5: Kavita Joshi | L5: 681 | M5: No
A6: TXN10005 | B6: CUST1006 | C6: Meera Nair | D6: Hyderabad | E6: Savings | F6: Credit | G6: 143603.35 | H6: 350961.16 | I6: 45506 | J6: Kurla | K6: Amit Patel | L6: 692 | M6: No
A7: TXN10006 | B7: CUST1007 | C7: Vivek Kumar | D7: Kolkata | E7: Current | F7: Debit | G7: 143095.48 | H7: 139817.16 | I7: 45295 | J7: Borivali | K7: Deepa Rao | L7: 661 | M7: No
A8: TXN10007 | B8: CUST1008 | C8: Priyanka Das | D8: Mumbai | E8: Fixed Deposit | F8: Transfer | G8: 139372.57 | H8: 170785.01 | I8: 45371 | J8: BKC | K8: Priya Sharma | L8: 690 | M8: No
A9: TXN10008 | B9: CUST1009 | C9: Sanjay Patel | D9: Delhi | E9: Recurring Deposit | F9: EMI | G9: 139014.45 | H9: 168960.68 | I9: 45339 | J9: Andheri | K9: Rahul Verma | L9: 774 | M9: Yes
A10: TXN10009 | B10: CUST1010 | C10: Ananya Reddy | D10: Pune | E10: NRI | F10: Interest | G10: 138991.86 | H10: 423899.69 | I10: 45601 | J10: Powai | K10: Anjali Mehta | L10: 715 | M10: No
A11: TXN10010 | B11: CUST1011 | C11: Kartik Mehta | D11: Bangalore | E11: Savings | F11: Credit | G11: 131868.92 | H11: 365136.16 | I11: 45566 | J11: Thane | K11: Suresh Nair | L11: 643 | M11: No
A12: TXN10011 | B12: CUST1012 | C12: Divya Rao | D12: Chennai | E12: Current | F12: Debit | G12: 126329.57 | H12: 189888.65 | I12: 45574 | J12: Dadar | K12: Kavita Joshi | L12: 730 | M12: No
A13: TXN10012 | B13: CUST1013 | C13: Arun Sharma | D13: Hyderabad | E13: Fixed Deposit | F13: Transfer | G13: 124496 | H13: 309641.36 | I13: 45477 | J13: Kurla | K13: Amit Patel | L13: 678 | M13: No
... A54: TXN10053 | B54: CUST1004 | C54: Sunita Verma | D54: Chennai | E54: Recurring Deposit | F54: EMI | G54: 35282.8 | H54: 364378.58 | I54: 45347 | J54: Dadar | K54: Kavita Joshi | L54: 707 | M54: No
A55: TXN10054 | B55: CUST1005 | C55: Rajesh Kapoor | D55: Hyderabad | E55: NRI | F55: Interest | G55: 34726.8 | H55: 268606.59 | I55: 45363 | J55: Kurla | K55: Amit Patel | L55: 796 | M55: Yes | R55: =NETWORKDAYS(I52,TODAY()) -> 528
A56: TXN10055 | B56: CUST1006 | C56: Nandita Bose | D56: Kolkata | E56: Savings | F56: Credit | G56: 34092.25 | H56: 231851.41 | I56: 45330 | J56: Borivali | K56: Deepa Rao | L56: 806 | M56: Yes
A57: TXN10056 | B57: CUST1007 | C57: Harish Pillai | D57: Mumbai | E57: Current | F57: Debit | G57: 33870.01 | H57: 428127.48 | I57: 45342 | J57: BKC | K57: Priya Sharma | L57: 605 | M57: No
A58: TXN10057 | B58: CUST1008 | C58: Swati Desai | D58: Delhi | E58: Fixed Deposit | F58: Transfer | G58: 32287.67 | H58: 270753.38 | I58: 45299 | J58: Andheri | K58: Rahul Verma | L58: 627 | M58: No
A59: TXN10058 | B59: CUST1009 | C59: Mohit Goel | D59: Pune | E59: Recurring Deposit | F59: EMI | G59: 29142.72 | H59: 424499.17 | I59: 45377 | J59: Powai | K59: Anjali Mehta | L59: 788 | M59: Yes
A60: TXN10059 | B60: CUST1010 | C60: Tanvi Mishra | D60: Bangalore | E60: NRI | F60: Interest | G60: 27931.46 | H60: 107659.9 | I60: 45497 | J60: Thane | K60: Suresh Nair | L60: 610 | M60: No
A61: TXN10060 | B61: CUST1011 | C61: Rohan Gupta | D61: Chennai | E61: Savings | F61: Credit | G61: 25113.25 | H61: 2075.53 | I61: 45491 | J61: Dadar | K61: Kavita Joshi | L61: 715 | M61: No
A62: TXN10061 | B62: CUST1012 | C62: Sneha Iyer | D62: Hyderabad | E62: Current | F62: Debit | G62: 23642.13 | H62: 392779.55 | I62: 45438 | J62: Kurla | K62: Amit Patel | L62: 796 | M62: Yes
A63: TXN10062 | B63: CUST1013 | C63: Arjun Singh | D63: Kolkata | E63: Fixed Deposit | F63: Transfer | G63: 21859.3 | H63: 365522.15 | I63: 45576 | J63: Borivali | K63: Deepa Rao | L63: 829 | M63: Yes
A64: TXN10063 | B64: CUST1014 | C64: Pooja Shah | D64: Mumbai | E64: Recurring Deposit | F64: EMI | G64: 19694.52 | H64: 149057.2 | I64: 45321 | J64: BKC | K64: Priya Sharma | L64: 611 | M64: No
A65: TXN10064 | B65: CUST1015 | C65: Nikhil Jain | D65: Delhi | E65: NRI | F65: Interest | G65: 18423.05 | H65: 29525.47 | I65: 45591 | J65: Andheri | K65: Rahul Verma | L65: 824 | M65: Yes
A66: TXN10065 | B66: CUST1016 | C66: Meera Nair | D66: Pune | E66: Savings | F66: Credit | G66: 17177.05 | H66: 426507.23 | I66: 45372 | J66: Powai | K66: Anjali Mehta | L66: 609 | M66: No
A67: TXN10066 | B67: CUST1017 | C67: Vivek Kumar | D67: Bangalore | E67: Current | F67: Debit | G67: 14959.1 | H67: 40975.62 | I67: 45387 | J67: Thane | K67: Suresh Nair | L67: 615 | M67: No
... A71: TXN10070 | B71: CUST1021 | C71: Kartik Mehta | D71: Mumbai | E71: Savings | F71: Credit | G71: 9159.81 | H71: 131122.08 | I71: 45634 | J71: BKC | K71: Priya Sharma | L71: 740 | M71: No
M72: =N56 -> 0
M73: =COUNTIF(M9:M70,"yes") -> 20

Sheet Sheet2
